Workbook
Name CicloObjetivo: Parametros!$B$4
Name VentanaCosecha: Parametros!$B$5

Sheet Dashboard Ciclos
A1: 🌴 CICLOS DE COSECHA · Vitis Olei
A2: Fecha del informe: | B2: 46249 | D2: ="Universo: "&COUNTA('Registro Diario'!$E$2:$E$126)&" lotes · "&COUNTIFS('Registro Diario'!$R$2:$R$126,"<>",'Registro Diario'!$R$2:$R$126,">=0")&" productivos · "&COUNTIF('Registro Diario'!$S$2:$S$126,"Sin dato")&" en desarrollo (sin ciclo)" -> Universo: 125 lotes · 94 productivos · 31 en desarrollo (sin ciclo)
A4: 🌾 RECIÉN CORTADO (<5 días) | C4: ✅ EN CICLO (5–12 días) | E4: ⚠️ FUERA DE CICLO (>12 días) | G4: 🔴 MAYOR CICLO (días)
A5: =ROUND(SUMIFS('Registro Diario'!$J$2:$J$126,'Registro Diario'!$T$2:$T$126,"Recién cortado"),1) -> 731 | C5: =ROUND(SUMIFS('Registro Diario'!$J$2:$J$126,'Registro Diario'!$T$2:$T$126,"En ciclo"),1) -> 949.3 | E5: =ROUND(SUMIFS('Registro Diario'!$J$2:$J$126,'Registro Diario'!$T$2:$T$126,"Fuera de ciclo"),1) -> 655.9 | G5: =MAX('Registro Diario'!$R$2:$R$126) -> 22
A6: =COUNTIFS('Registro Diario'!$T$2:$T$126,"Recién cortado")&" lotes · hás" -> 25 lotes · hás | C6: =COUNTIFS('Registro Diario'!$T$2:$T$126,"En ciclo")&" lotes · hás" -> 44 lotes · hás | E6: =COUNTIFS('Registro Diario'!$T$2:$T$126,"Fuera de ciclo")&" lotes · hás" -> 25 lotes · hás | G6: =INDEX('Registro Diario'!$E$2:$E$126,MATCH(MAX('Registro Diario'!$R$2:$R$126),'Registro Diario'!$R$2:$R$126,0)) -> La Pradera-42
A8: INFORME GENERAL
A9: Estado ciclo | B9: Hás | C9: # Lotes | D9: % Hás | E9: Equivalencia
A10: En ciclo | B10: =ROUND(SUMIFS('Registro Diario'!$J$2:$J$126,'Registro Diario'!$S$2:$S$126,$A10),1) -> 1680.3 | C10: =COUNTIFS('Registro Diario'!$S$2:$S$126,$A10) -> 69 | D10: =IF($B$15=0,0,B10/$B$15) -> 0.71927572 | E10: ciclo ≤ 12 días
A11: Vencido 1-5 d | B11: =ROUND(SUMIFS('Registro Diario'!$J$2:$J$126,'Registro Diario'!$S$2:$S$126,$A11),1) -> 493.4 | C11: =COUNTIFS('Registro Diario'!$S$2:$S$126,$A11) -> 20 | D11: =IF($B$15=0,0,B11/$B$15) -> 0.21120671 | E11: ciclo 13–17 d
A12: Vencido 6-10 d | B12: =ROUND(SUMIFS('Registro Diario'!$J$2:$J$126,'Registro Diario'!$S$2:$S$126,$A12),1) -> 162.4 | C12: =COUNTIFS('Registro Diario'!$S$2:$S$126,$A12) -> 5 | D12: =IF($B$15=0,0,B12/$B$15) -> 0.069517572 | E12: ciclo 18–22 d
A13: Vencido 11-15 d | B13: =ROUND(SUMIFS('Registro Diario'!$J$2:$J$126,'Registro Diario'!$S$2:$S$126,$A13),1) -> 0 | C13: =COUNTIFS('Registro Diario'!$S$2:$S$126,$A13) -> 0 | D13: =IF($B$15=0,0,B13/$B$15) -> 0 | E13: ciclo 23–27 d
A14: Vencido +15 d | B14: =ROUND(SUMIFS('Registro Diario'!$J$2:$J$126,'Registro Diario'!$S$2:$S$126,$A14),1) -> 0 | C14: =COUNTIFS('Registro Diario'!$S$2:$S$126,$A14) -> 0 | D14: =IF($B$15=0,0,B14/$B$15) -> 0 | E14: ciclo ≥ 28 d
A15: Total con dato | B15: =SUM(B10:B14) -> 2336.1 | C15: =SUM(C10:C14) -> 94 | D15: =IF($B$15=0,0,B15/$B$15) -> 1
A32: INFORME POR ZONA (Hás)
A33: Zona | B33: En ciclo | C33: Vencido 1-5 d | D33: Vencido 6-10 d | E33: Vencido 11-15 d | F33: Vencido +15 d | G33: Total fuera | H33: Mayor ciclo | I33: Lote mayor ciclo
A34: 1 | B34: =ROUND(SUMIFS('Registro Diario'!$J$2:$J$126,'Registro Diario'!$B$2:$B$126,$A34,'Registro Diario'!$S$2:$S$126,"En ciclo"),1) -> 216.3 | C34: =ROUND(SUMIFS('Registro Diario'!$J$2:$J$126,'Registro Diario'!$B$2:$B$126,$A34,'Registro Diario'!$S$2:$S$126,"Vencido 1-5 d"),1) -> 224.7 | D34: =ROUND(SUMIFS('Registro Diario'!$J$2:$J$126,'Registro Diario'!$B$2:$B$126,$A34,'Registro Diario'!$S$2:$S$126,"Vencido 6-10 d"),1) -> 104.5 | E34: =ROUND(SUMIFS('Registro Diario'!$J$2:$J$126,'Registro Diario'!$B$2:$B$126,$A34,'Registro Diario'!$S$2:$S$126,"Vencido 11-15 d"),1) -> 0 | F34: =ROUND(SUMIFS('Registro Diario'!$J$2:$J$126,'Registro Diario'!$B$2:$B$126,$A34,'Registro Diario'!$S$2:$S$126,"Vencido +15 d"),1) -> 0 | G34: =SUM(C34:F34) -> 329.2 | H34: =IFERROR(_xlfn.MAXIFS('Registro Diario'!$R$2:$R$126,'Registro Diario'!$B$2:$B$126,$A34),0) -> 19 | I34: =IFERROR(INDEX('Registro Diario'!$E$2:$E$126,MATCH(1,INDEX(('Registro Diario'!$R$2:$R$126=$H34)*('Registro Diario'!$B$2:$B$126=$A34),0),0)),"—") -> El Cristal-12
A35: 2 | B35: =ROUND(SUMIFS('Registro Diario'!$J$2:$J$126,'Registro Diario'!$B$2:$B$126,$A35,'Registro Diario'!$S$2:$S$126,"En ciclo"),1) -> 480.7 | C35: =ROUND(SUMIFS('Registro Diario'!$J$2:$J$126,'Registro Diario'!$B$2:$B$126,$A35,'Registro Diario'!$S$2:$S$126,"Vencido 1-5 d"),1) -> 47.8 | D35: =ROUND(SUMIFS('Registro Diario'!$J$2:$J$126,'Registro Diario'!$B$2:$B$126,$A35,'Registro Diario'!$S$2:$S$126,"Vencido 6-10 d"),1) -> 0 | E35: =ROUND(SUMIFS('Registro Diario'!$J$2:$J$126,'Registro Diario'!$B$2:$B$126,$A35,'Registro Diario'!$S$2:$S$126,"Vencido 11-15 d"),1) -> 0 | F35: =ROUND(SUMIFS('Registro Diario'!$J$2:$J$126,'Registro Diario'!$B$2:$B$126,$A35,'Registro Diario'!$S$2:$S$126,"Vencido +15 d"),1) -> 0 | G35: =SUM(C35:F35) -> 47.8 | H35: =IFERROR(_xlfn.MAXIFS('Registro Diario'!$R$2:$R$126,'Registro Diario'!$B$2:$B$126,$A35),0) -> 15 | I35: =IFERROR(INDEX('Registro Diario'!$E$2:$E$126,MATCH(1,INDEX(('Registro Diario'!$R$2:$R$126=$H35)*('Registro Diario'!$B$2:$B$126=$A35),0),0)),"—") -> La Vitrina-22
A36: 3 | B36: =ROUND(SUMIFS('Registro Diario'!$J$2:$J$126,'Registro Diario'!$B$2:$B$126,$A36,'Registro Diario'!$S$2:$S$126,"En ciclo"),1) -> 393.1 | C36: =ROUND(SUMIFS('Registro Diario'!$J$2:$J$126,'Registro Diario'!$B$2:$B$126,$A36,'Registro Diario'!$S$2:$S$126,"Vencido 1-5 d"),1) -> 87.8 | D36: =ROUND(SUMIFS('Registro Diario'!$J$2:$J$126,'Registro Diario'!$B$2:$B$126,$A36,'Registro Diario'!$S$2:$S$126,"Vencido 6-10 d"),1) -> 57.9 | E36: =ROUND(SUMIFS('Registro Diario'!$J$2:$J$126,'Registro Diario'!$B$2:$B$126,$A36,'Registro Diario'!$S$2:$S$126,"Vencido 11-15 d"),1) -> 0 | F36: =ROUND(SUMIFS('Registro Diario'!$J$2:$J$126,'Registro Diario'!$B$2:$B$126,$A36,'Registro Diario'!$S$2:$S$126,"Vencido +15 d"),1) -> 0 | G36: =SUM(C36:F36) -> 145.7 | H36: =IFERROR(_xlfn.MAXIFS('Registro Diario'!$R$2:$R$126,'Registro Diario'!$B$2:$B$126,$A36),0) -> 22 | I36: =IFERROR(INDEX('Registro Diario'!$E$2:$E$126,MATCH(1,INDEX(('Registro Diario'!$R$2:$R$126=$H36)*('Registro Diario'!$B$2:$B$126=$A36),0),0)),"—") -> La Pradera-42
A37: 4 | B37: =ROUND(SUMIFS('Registro Diario'!$J$2:$J$126,'Registro Diario'!$B$2:$B$126,$A37,'Registro Diario'!$S$2:$S$126,"En ciclo"),1) -> 506.3 | C37: =ROUND(SUMIFS('Registro Diario'!$J$2:$J$126,'Registro Diario'!$B$2:$B$126,$A37,'Registro Diario'!$S$2:$S$126,"Vencido 1-5 d"),1) -> 30.1 | D37: =ROUND(SUMIFS('Registro Diario'!$J$2:$J$126,'Registro Diario'!$B$2:$B$126,$A37,'Registro Diario'!$S$2:$S$126,"Vencido 6-10 d"),1) -> 0 | E37: =ROUND(SUMIFS('Registro Diario'!$J$2:$J$126,'Registro Diario'!$B$2:$B$126,$A37,'Registro Diario'!$S$2:$S$126,"Vencido 11-15 d"),1) -> 0 | F37: =ROUND(SUMIFS('Registro Diario'!$J$2:$J$126,'Registro Diario'!$B$2:$B$126,$A37,'Registro Diario'!$S$2:$S$126,"Vencido +15 d"),1) -> 0 | G37: =SUM(C37:F37) -> 30.1 | H37: =IFERROR(_xlfn.MAXIFS('Registro Diario'!$R$2:$R$126,'Registro Diario'!$B$2:$B$126,$A37),0) -> 14 | I37: =IFERROR(INDEX('Registro Diario'!$E$2:$E$126,MATCH(1,INDEX(('Registro Diario'!$R$2:$R$126=$H37)*('Registro Diario'!$B$2:$B$126=$A37),0),0)),"—") -> Rines-61
A38: 5 | B38: =ROUND(SUMIFS('Registro Diario'!$J$2:$J$126,'Registro Diario'!$B$2:$B$126,$A38,'Registro Diario'!$S$2:$S$126,"En ciclo"),1) -> 84 | C38: =ROUND(SUMIFS('Registro Diario'!$J$2:$J$126,'Registro Diario'!$B$2:$B$126,$A38,'Registro Diario'!$S$2:$S$126,"Vencido 1-5 d"),1) -> 103 | D38: =ROUND(SUMIFS('Registro Diario'!$J$2:$J$126,'Registro Diario'!$B$2:$B$126,$A38,'Registro Diario'!$S$2:$S$126,"Vencido 6-10 d"),1) -> 0 | E38: =ROUND(SUMIFS('Registro Diario'!$J$2:$J$126,'Registro Diario'!$B$2:$B$126,$A38,'Registro Diario'!$S$2:$S$126,"Vencido 11-15 d"),1) -> 0 | F38: =ROUND(SUMIFS('Registro Diario'!$J$2:$J$126,'Registro Diario'!$B$2:$B$126,$A38,'Registro Diario'!$S$2:$S$126,"Vencido +15 d"),1) -> 0 | G38: =SUM(C38:F38) -> 103 | H38: =IFERROR(_xlfn.MAXIFS('Registro Diario'!$R$2:$R$126,'Registro Diario'!$B$2:$B$126,$A38),0) -> 16 | I38: =IFERROR(INDEX('Registro Diario'!$E$2:$E$126,MATCH(1,INDEX(('Registro Diario'!$R$2:$R$126=$H38)*('Registro Diario'!$B$2:$B$126=$A38),0),0)),"—") -> Paso Barinas-2A
A39: Total | B39: =SUM(B34:B38) -> 1680.4 | C39: =SUM(C34:C38) -> 493.4 | D39: =SUM(D34:D38) -> 162.4 | E39: =SUM(E34:E38) -> 0 | F39: =SUM(F34:F38) -> 0 | G39: =SUM(G34:G38) -> 655.8 | H39: =MAX(H34:H38) -> 22
A41: PARTICIPACIÓN % POR ZONA (sobre hás con dato de cada zona)
A42: Zona | B42: En ciclo | C42: Vencido 1-5 d | D42: Vencido 6-10 d | E42: Vencido 11-15 d | F42: Vencido +15 d | G42: Total hás zona
A43: =A34 -> 1 | B43: =IF($B34+$G34=0,0,B34/($B34+$G34)) -> 0.39651696 | C43: =IF($B34+$G34=0,0,C34/($B34+$G34)) -> 0.41191567 | D43: =IF($B34+$G34=0,0,D34/($B34+$G34)) -> 0.19156737 | E43: =IF($B34+$G34=0,0,E34/($B34+$G34)) -> 0 | F43: =IF($B34+$G34=0,0,F34/($B34+$G34)) -> 0 | G43: =B34+G34 -> 545.5
A44: =A35 -> 2 | B44: =IF($B35+$G35=0,0,B35/($B35+$G35)) -> 0.90955535 | C44: =IF($B35+$G35=0,0,C35/($B35+$G35)) -> 0.090444655 | D44: =IF($B35+$G35=0,0,D35/($B35+$G35)) -> 0 | E44: =IF($B35+$G35=0,0,E35/($B35+$G35)) -> 0 | F44: =IF($B35+$G35=0,0,F35/($B35+$G35)) -> 0 | G44: =B35+G35 -> 528.5
A45: =A36 -> 3 | B45: =IF($B36+$G36=0,0,B36/($B36+$G36)) -> 0.72958426 | C45: =IF($B36+$G36=0,0,C36/($B36+$G36)) -> 0.16295471 | D45: =IF($B36+$G36=0,0,D36/($B36+$G36)) -> 0.10746102 | E45: =IF($B36+$G36=0,0,E36/($B36+$G36)) -> 0 | F45: =IF($B36+$G36=0,0,F36/($B36+$G36)) -> 0 | G45: =B36+G36 -> 538.8
A46: =A37 -> 4 | B46: =IF($B37+$G37=0,0,B37/($B37+$G37)) -> 0.94388516 | C46: =IF($B37+$G37=0,0,C37/($B37+$G37)) -> 0.05611484 | D46: =IF($B37+$G37=0,0,D37/($B37+$G37)) -> 0 | E46: =IF($B37+$G37=0,0,E37/($B37+$G37)) -> 0 | F46: =IF($B37+$G37=0,0,F37/($B37+$G37)) -> 0 | G46: =B37+G37 -> 536.4
A47: =A38 -> 5 | B47: =IF($B38+$G38=0,0,B38/($B38+$G38)) -> 0.44919786 | C47: =IF($B38+$G38=0,0,C38/($B38+$G38)) -> 0.55080214 | D47: =IF($B38+$G38=0,0,D38/($B38+$G38)) -> 0 | E47: =IF($B38+$G38=0,0,E38/($B38+$G38)) -> 0 | F47: =IF($B38+$G38=0,0,F38/($B38+$G38)) -> 0 | G47: =B38+G38 -> 187
A48: Total | B48: =IF($B$39+$G$39=0,0,B39/($B$39+$G$39)) -> 0.71928773 | C48: =IF($B$39+$G$39=0,0,C39/($B$39+$G$39)) -> 0.21119767 | D48: =IF($B$39+$G$39=0,0,D39/($B$39+$G$39)) -> 0.069514596 | E48: =IF($B$39+$G$39=0,0,E39/($B$39+$G$39)) -> 0 | F48: =IF($B$39+$G$39=0,0,F39/($B$39+$G$39)) -> 0 | G48: =B39+G39 -> 2336.2
A50: GLOSARIO DE ESTADOS
A51: Estado | B51: Descripción
A52: Recién cortado | B52: Ciclo < 5 días desde el último corte. El lote acaba de ser cosechado.
A53: En ciclo | B53: 5 – 12 días desde el corte. Lote dentro del ventana de cosecha óptima.
A54: Vencido 1-5 d | B54: Ciclo 13–17 días. Fuera de ciclo, urgencia baja.
A55: Vencido 6-10 d | B55: Ciclo 18–22 días. Fuera de ciclo, urgencia media.
A56: Vencido 11-15 d | B56: Ciclo 23–27 días. Fuera de ciclo, urgencia alta. Pérdida de calidad probable.
A57: Vencido +15 d | B57: Ciclo ≥ 28 días. Fuera de ciclo crítico. Pérdida de calidad y TEA.
A58: Sin dato | B58: Lote En Desarrollo: no tiene ciclo activo, excluido del cómputo de hás.
A81: 🔍 CONSULTA INTERACTIVA POR ZONA
A82: Seleccione zona ▼ | B82: 4 | C82: ← Todas, 1, 2, 3, 4 o 5
...

Sheet Registro Diario
A1: Plantación | B1: Zona | C1: Finca | D1: Lote | E1: Lote (llave) | F1: Material | G1: Casa Comercial | H1: Año Siembra | I1: Edad | J1: Hás | K1: No Palmas MD | L1: Total Palmas | M1: Palmas sin RH 2026 | N1: Propietario | O1: Tipo Operación | P1: Estado | Q1: Fecha último corte | R1: Ciclo Hoy | S1: Estado ciclo | T1: Condición | U1: Días p/ vencer | V1: Fecha venc. proyectada | W1: =DATE(2026,7,1) -> 46204 | X1: =W1+1 -> 46205 | Y1: =X1+1 -> 46206 | Z1: =Y1+1 -> 46207 | AA1: =Z1+1 -> 46208 | AB1: =AA1+1 -> 46209 | AC1: =AB1+1 -> 46210 | AD1: =AC1+1 -> 46211 | AE1: =AD1+1 -> 46212 | ... GX1: =GW1+1 -> 46387
A2: Vitis | B2: 1 | C2: El Cristal | D2: 1 | E2: El Cristal-1 | F2: Deli x La Me | G2: Irho | H2: 2009 | I2: 17 | J2: 39.38 | K2: 179 | L2: 5644 | M2: 5465 | N2: Capitales y proyectos | O2: Administrado | P2: Productivo | Q2: =IF(R2="","",'Dashboard Ciclos'!$B$2-R2) -> 46231 | R2: =IF($E2="","",IFERROR(INDEX($W2:$GX2,MATCH('Dashboard Ciclos'!$B$2,$W$1:$GX$1,0)),"")) -> 18 | S2: =IF($Q2="","Sin dato",IF($R2<=CicloObjetivo,"En ciclo",IF($R2-CicloObjetivo<=5,"Vencido 1-5 d",IF($R2-CicloObjetivo<=10,"Vencido 6-10 d",IF($R2-CicloObjetivo<=15,"Vencido 11-15 d","Vencido +15 d"))))) -> Vencido 6-10 d | T2: =IF($Q2="","Sin dato",IF($R2<VentanaCosecha,"Recién cortado",IF($R2<=CicloObjetivo,"En ciclo","Fuera de ciclo"))) -> Fuera de ciclo | U2: =IF($Q2="","",CicloObjetivo-$R2) -> -6 | V2: =IF($Q2="","",$Q2+CicloObjetivo) -> 46243 | W2: =+X2-1 -> 30 | X2: =+Y2-1 -> 31 | Y2: =+Z2-1 -> 32 | Z2: =+AA2-1 -> 33 | AA2: 34 | AB2: 0 | AC2: =IF(AB2="","",AB2+1) -> 1 | AD2: =IF(AC2="","",AC2+1) -> 2 | AE2: =IF(AD2="","",AD2+1) -> 3 | AF2: =IF(AE2="","",AE2+1) -> 4 | AG2: =IF(AF2="","",AF2+1) -> 5 | AH2: =IF(AG2="","",AG2+1) -> 6 | AI2: =IF(AH2="","",AH2+1) -> 7 | AJ2: =IF(AI2="","",AI2+1) -> 8 | ... AW2: =IF(AV2="","",AV2+1) -> 21 | AX2: 0 | AY2: =IF(AX2="","",AX2+1) -> 1 | AZ2: =IF(AY2="","",AY2+1) -> 2 | BA2: =IF(AZ2="","",AZ2+1) -> 3 | BB2: =IF(BA2="","",BA2+1) -> 4 | BC2: =IF(BB2="","",BB2+1) -> 5 | BD2: =IF(BC2="","",BC2+1) -> 6 | BE2: =IF(BD2="","",BD2+1) -> 7 | BF2: =IF(BE2="","",BE2+1) -> 8 | ... GX2: =IF(GW2="","",GW2+1) -> 156
A3: Vitis | B3: 1 | C3: El Cristal | D3: 2 | E3: El Cristal-2 | F3: Deli x La Me | G3: Irho | H3: 2009 | I3: 17 | J3: 55.25 | K3: 0 | L3: 7820 | M3: 7820 | N3: Capitales y proyectos | O3: Administrado | P3: Productivo | Q3: =IF(R3="","",'Dashboard Ciclos'!$B$2-R3) -> 46232 | R3: =IF($E3="","",IFERROR(INDEX($W3:$GX3,MATCH('Dashboard Ciclos'!$B$2,$W$1:$GX$1,0)),"")) -> 17 | S3: =IF($Q3="","Sin dato",IF($R3<=CicloObjetivo,"En ciclo",IF($R3-CicloObjetivo<=5,"Vencido 1-5 d",IF($R3-CicloObjetivo<=10,"Vencido 6-10 d",IF($R3-CicloObjetivo<=15,"Vencido 11-15 d","Vencido +15 d"))))) -> Vencido 1-5 d | T3: =IF($Q3="","Sin dato",IF($R3<VentanaCosecha,"Recién cortado",IF($R3<=CicloObjetivo,"En ciclo","Fuera de ciclo"))) -> Fuera de ciclo | U3: =IF($Q3="","",CicloObjetivo-$R3) -> -5 | V3: =IF($Q3="","",$Q3+CicloObjetivo) -> 46244 | W3: =+X3-1 -> 28 | X3: =+Y3-1 -> 29 | Y3: =+Z3-1 -> 30 | Z3: =+AA3-1 -> 31 | AA3: 32 | AB3: =IF(AA3="","",AA3+1) -> 33 | AC3: =IF(AB3="","",AB3+1) -> 34 | AD3: =IF(AC3="","",AC3+1) -> 35 | AE3: 0 | AF3: =IF(AE3="","",AE3+1) -> 1 | AG3: =IF(AF3="","",AF3+1) -> 2 | AH3: =IF(AG3="","",AG3+1) -> 3 | AI3: =IF(AH3="","",AH3+1) -> 4 | AJ3: =IF(AI3="","",AI3+1) -> 5 | AK3: =IF(AJ3="","",AJ3+1) -> 6 | AL3: =IF(AK3="","",AK3+1) -> 7 | AM3: =IF(AL3="","",AL3+1) -> 8 | ... AX3: =IF(AW3="","",AW3+1) -> 19 | AY3: 0 | AZ3: =IF(AY3="","",AY3+1) -> 1 | BA3: =IF(AZ3="","",AZ3+1) -> 2 | BB3: =IF(BA3="","",BA3+1) -> 3 | BC3: =IF(BB3="","",BB3+1) -> 4 | BD3: =IF(BC3="","",BC3+1) -> 5 | BE3: =IF(BD3="","",BD3+1) -> 6 | BF3: =IF(BE3="","",BE3+1) -> 7 | BG3: =IF(BF3="","",BF3+1) -> 8 | ... GX3: =IF(GW3="","",GW3+1) -> 155
A4: Vitis | B4: 1 | C4: El Cristal | D4: 3 | E4: El Cristal-3 | F4: Deli x Mezcla | G4: Mezcla | H4: 2009 | I4: 17 | J4: 37.93 | K4: 0 | L4: 5368 | M4: 5368 | N4: Capitales y proyectos | O4: Administrado | P4: Productivo | Q4: =IF(R4="","",'Dashboard Ciclos'!$B$2-R4) -> 46233 | R4: =IF($E4="","",IFERROR(INDEX($W4:$GX4,MATCH('Dashboard Ciclos'!$B$2,$W$1:$GX$1,0)),"")) -> 16 | S4: =IF($Q4="","Sin dato",IF($R4<=CicloObjetivo,"En ciclo",IF($R4-CicloObjetivo<=5,"Vencido 1-5 d",IF($R4-CicloObjetivo<=10,"Vencido 6-10 d",IF($R4-CicloObjetivo<=15,"Vencido 11-15 d","Vencido +15 d"))))) -> Vencido 1-5 d | T4: =IF($Q4="","Sin dato",IF($R4<VentanaCosecha,"Recién cortado",IF($R4<=CicloObjetivo,"En ciclo","Fuera de ciclo"))) -> Fuera de ciclo | U4: =IF($Q4="","",CicloObjetivo-$R4) -> -4 | V4: =IF($Q4="","",$Q4+CicloObjetivo) -> 46245 | W4: =+X4-1 -> 28 | X4: =+Y4-1 -> 29 | Y4: =+Z4-1 -> 30 | Z4: =+AA4-1 -> 31 | AA4: 32 | AB4: =IF(AA4="","",AA4+1) -> 33 | AC4: =IF(AB4="","",AB4+1) -> 34 | AD4: =IF(AC4="","",AC4+1) -> 35 | AE4: =IF(AD4="","",AD4+1) -> 36 | AF4: =IF(AE4="","",AE4+1) -> 37 | AG4: =IF(AF4="","",AF4+1) -> 38 | AH4: 0 | AI4: =IF(AH4="","",AH4+1) -> 1 | AJ4: =IF(AI4="","",AI4+1) -> 2 | AK4: =IF(AJ4="","",AJ4+1) -> 3 | AL4: =IF(AK4="","",AK4+1) -> 4 | AM4: =IF(AL4="","",AL4+1) -> 5 | AN4: =IF(AM4="","",AM4+1) -> 6 | AO4: =IF(AN4="","",AN4+1) -> 7 | AP4: =IF(AO4="","",AO4+1) -> 8 | ... AY4: =IF(AX4="","",AX4+1) -> 17 | AZ4: 0 | BA4: =IF(AZ4="","",AZ4+1) -> 1 | BB4: =IF(BA4="","",BA4+1) -> 2 | BC4: =IF(BB4="","",BB4+1) -> 3 | BD4: =IF(BC4="","",BC4+1) -> 4 | BE4: =IF(BD4="","",BD4+1) -> 5 | BF4: =IF(BE4="","",BE4+1) -> 6 | BG4: =IF(BF4="","",BF4+1) -> 7 | BH4: =IF(BG4="","",BG4+1) -> 8 | ... GX4: =IF(GW4="","",GW4+1) -> 154
A5: Vitis | B5: 1 | C5: El Cristal | D5: 4 | E5: El Cristal-4 | F5: Deli x Nigeria | G5: Asd | H5: 2009 | I5: 17 | J5: 48.81 | K5: 0 | L5: 6820 | M5: 6820 | N5: Capitales y proyectos | O5: Administrado | P5: Productivo | Q5: =IF(R5="","",'Dashboard Ciclos'!$B$2-R5) -> 46234 | R5: =IF($E5="","",IFERROR(INDEX($W5:$GX5,MATCH('Dashboard Ciclos'!$B$2,$W$1:$GX$1,0)),"")) -> 15 | S5: =IF($Q5="","Sin dato",IF($R5<=CicloObjetivo,"En ciclo",IF($R5-CicloObjetivo<=5,"Vencido 1-5 d",IF($R5-CicloObjetivo<=10,"Vencido 6-10 d",IF($R5-CicloObjetivo<=15,"Vencido 11-15 d","Vencido +15 d"))))) -> Vencido 1-5 d | T5: =IF($Q5="","Sin dato",IF($R5<VentanaCosecha,"Recién cortado",IF($R5<=CicloObjetivo,"En ciclo","Fuera de ciclo"))) -> Fuera de ciclo | U5: =IF($Q5="","",CicloObjetivo-$R5) -> -3 | V5: =IF($Q5="","",$Q5+CicloObjetivo) -> 46246 | W5: =+X5-1 -> 22 | X5: =+Y5-1 -> 23 | Y5: =+Z5-1 -> 24 | Z5: =+AA5-1 -> 25 | AA5: 26 | AB5: =IF(AA5="","",AA5+1) -> 27 | AC5: =IF(AB5="","",AB5+1) -> 28 | AD5: =IF(AC5="","",AC5+1) -> 29 | AE5: =IF(AD5="","",AD5+1) -> 30 | AF5: =IF(AE5="","",AE5+1) -> 31 | AG5: =IF(AF5="","",AF5+1) -> 32 | AH5: =IF(AG5="","",AG5+1) -> 33 | AI5: 0 | AJ5: =IF(AI5="","",AI5+1) -> 1 | AK5: =IF(AJ5="","",AJ5+1) -> 2 | AL5: =IF(AK5="","",AK5+1) -> 3 | AM5: =IF(AL5="","",AL5+1) -> 4 | AN5: =IF(AM5="","",AM5+1) -> 5 | AO5: =IF(AN5="","",AN5+1) -> 6 | AP5: =IF(AO5="","",AO5+1) -> 7 | AQ5: =IF(AP5="","",AP5+1) -> 8 | ... AZ5: =IF(AY5="","",AY5+1) -> 17 | BA5: 0 | BB5: =IF(BA5="","",BA5+1) -> 1 | BC5: =IF(BB5="","",BB5+1) -> 2 | BD5: =IF(BC5="","",BC5+1) -> 3 | BE5: =IF(BD5="","",BD5+1) -> 4 | BF5: =IF(BE5="","",BE5+1) -> 5 | BG5: =IF(BF5="","",BF5+1) -> 6 | BH5: =IF(BG5="","",BG5+1) -> 7 | BI5: =IF(BH5="","",BH5+1) -> 8 | ... GX5: =IF(GW5="","",GW5+1) -> 153
A6: Vitis | B6: 1 | C6: El Cristal | D6: 5 | E6: El Cristal-5 | F6: Deli x Nigeria | G6: Asd | H6: 2009 | I6: 17 | J6: 43.08 | K6: 0 | L6: 5950 | M6: 5950 | N6: Capitales y proyectos | O6: Administrado | P6: Productivo | Q6: =IF(R6="","",'Dashboard Ciclos'!$B$2-R6) -> 46234 | R6: =IF($E6="","",IFERROR(INDEX($W6:$GX6,MATCH('Dashboard Ciclos'!$B$2,$W$1:$GX$1,0)),"")) -> 15 | S6: =IF($Q6="","Sin dato",IF($R6<=CicloObjetivo,"En ciclo",IF($R6-CicloObjetivo<=5,"Vencido 1-5 d",IF($R6-CicloObjetivo<=10,"Vencido 6-10 d",IF($R6-CicloObjetivo<=15,"Vencido 11-15 d","Vencido +15 d"))))) -> Vencido 1-5 d | T6: =IF($Q6="","Sin dato",IF($R6<VentanaCosecha,"Recién cortado",IF($R6<=CicloObjetivo,"En ciclo","Fuera de ciclo"))) -> Fuera de ciclo | U6: =IF($Q6="","",CicloObjetivo-$R6) -> -3 | V6: =IF($Q6="","",$Q6+CicloObjetivo) -> 46246 | W6: =+X6-1 -> 21 | X6: =+Y6-1 -> 22 | Y6: =+Z6-1 -> 23 | Z6: =+AA6-1 -> 24 | AA6: 25 | AB6: =IF(AA6="","",AA6+1) -> 26 | AC6: =IF(AB6="","",AB6+1) -> 27 | AD6: =IF(AC6="","",AC6+1) -> 28 | AE6: =IF(AD6="","",AD6+1) -> 29 | AF6: =IF(AE6="","",AE6+1) -> 30 | AG6: =IF(AF6="","",AF6+1) -> 31 | AH6: =IF(AG6="","",AG6+1) -> 32 | AI6: =IF(AH6="","",AH6+1) -> 33 | AJ6: =IF(AI6="","",AI6+1) -> 34 | AK6: 0 | AL6: =IF(AK6="","",AK6+1) -> 1 | AM6: =IF(AL6="","",AL6+1) -> 2 | AN6: =IF(AM6="","",AM6+1) -> 3 | AO6: =IF(AN6="","",AN6+1) -> 4 | AP6: =IF(AO6="","",AO6+1) -> 5 | AQ6: =IF(AP6="","",AP6+1) -> 6 | AR6: =IF(AQ6="","",AQ6+1) -> 7 | AS6: =IF(AR6="","",AR6+1) -> 8 | ... AZ6: =IF(AY6="","",AY6+1) -> 15 | BA6: 0 | BB6: =IF(BA6="","",BA6+1) -> 1 | BC6: =IF(BB6="","",BB6+1) -> 2 | BD6: =IF(BC6="","",BC6+1) -> 3 | BE6: =IF(BD6="","",BD6+1) -> 4 | BF6: =IF(BE6="","",BE6+1) -> 5 | BG6: =IF(BF6="","",BF6+1) -> 6 | BH6: =IF(BG6="","",BG6+1) -> 7 | BI6: =IF(BH6="","",BH6+1) -> 8 | ... GX6: =IF(GW6="","",GW6+1) -> 153
A7: Vitis | B7: 1 | C7: El Cristal | D7: 6 | E7: El Cristal-6 | F7: Deli x La Me | G7: Irho | H7: 2009 | I7: 17 | J7: 39.67 | K7: 0 | L7: 5599 | M7: 5599 | N7: Capitales y proyectos | O7: Administrado | P7: Productivo | Q7: =IF(R7="","",'Dashboard Ciclos'!$B$2-R7) -> 46235 | R7: =IF($E7="","",IFERROR(INDEX($W7:$GX7,MATCH('Dashboard Ciclos'!$B$2,$W$1:$GX$1,0)),"")) -> 14 | S7: =IF($Q7="","Sin dato",IF($R7<=CicloObjetivo,"En ciclo",IF($R7-CicloObjetivo<=5,"Vencido 1-5 d",IF($R7-CicloObjetivo<=10,"Vencido 6-10 d",IF($R7-CicloObjetivo<=15,"Vencido 11-15 d","Vencido +15 d"))))) -> Vencido 1-5 d | T7: =IF($Q7="","Sin dato",IF($R7<VentanaCosecha,"Recién cortado",IF($R7<=CicloObjetivo,"En ciclo","Fuera de ciclo"))) -> Fuera de ciclo | U7: =IF($Q7="","",CicloObjetivo-$R7) -> -2 | V7: =IF($Q7="","",$Q7+CicloObjetivo) -> 46247 | W7: =+X7-1 -> 20 | X7: =+Y7-1 -> 21 | Y7: =+Z7-1 -> 22 | Z7: =+AA7-1 -> 23 | AA7: 24 | AB7: =IF(AA7="","",AA7+1) -> 25 | AC7: =IF(AB7="","",AB7+1) -> 26 | AD7: =IF(AC7="","",AC7+1) -> 27 | AE7: =IF(AD7="","",AD7+1) -> 28 | AF7: =IF(AE7="","",AE7+1) -> 29 | AG7: =IF(AF7="","",AF7+1) -> 30 | AH7: =IF(AG7="","",AG7+1) -> 31 | AI7: =IF(AH7="","",AH7+1) -> 32 | ... AK7: =IF(AJ7="","",AJ7+1) -> 34 | AL7: 0 | AM7: =IF(AL7="","",AL7+1) -> 1 | AN7: =IF(AM7="","",AM7+1) -> 2 | AO7: =IF(AN7="","",AN7+1) -> 3 | AP7: =IF(AO7="","",AO7+1) -> 4 | AQ7: =IF(AP7="","",AP7+1) -> 5 | AR7: =IF(AQ7="","",AQ7+1) -> 6 | AS7: =IF(AR7="","",AR7+1) -> 7 | AT7: =IF(AS7="","",AS7+1) -> 8 | ... BA7: =IF(AZ7="","",AZ7+1) -> 15 | BB7: 0 | BC7: =IF(BB7="","",BB7+1) -> 1 | BD7: =IF(BC7="","",BC7+1) -> 2 | BE7: =IF(BD7="","",BD7+1) -> 3 | BF7: =IF(BE7="","",BE7+1) -> 4 | BG7: =IF(BF7="","",BF7+1) -> 5 | BH7: =IF(BG7="","",BG7+1) -> 6 | BI7: =IF(BH7="","",BH7+1) -> 7 | BJ7: =IF(BI7="","",BI7+1) -> 8 | ... GX7: =IF(GW7="","",GW7+1) -> 152
A8: Vitis | B8: 1 | C8: El Cristal | D8: 7 | E8: El Cristal-7 | F8: Deli x Nigeria | G8: Asd | H8: 2009 | I8: 17 | J8: 21.52 | K8: 67 | L8: 2977 | M8: 2910 | N8: Capitales y proyectos | O8: Administrado | P8: Productivo | Q8: =IF(R8="","",'Dashboard Ciclos'!$B$2-R8) -> 46237 | R8: =IF($E8="","",IFERROR(INDEX($W8:$GX8,MATCH('Dashboard Ciclos'!$B$2,$W$1:$GX$1,0)),"")) -> 12 | S8: =IF($Q8="","Sin dato",IF($R8<=CicloObjetivo,"En ciclo",IF($R8-CicloObjetivo<=5,"Vencido 1-5 d",IF($R8-CicloObjetivo<=10,"Vencido 6-10 d",IF($R8-CicloObjetivo<=15,"Vencido 11-15 d","Vencido +15 d"))))) -> En ciclo | T8: =IF($Q8="","Sin dato",IF($R8<VentanaCosecha,"Recién cortado",IF($R8<=CicloObjetivo,"En ciclo","Fuera de ciclo"))) -> En ciclo | U8: =IF($Q8="","",CicloObjetivo-$R8) -> 0 | V8: =IF($Q8="","",$Q8+CicloObjetivo) -> 46249 | W8: =+X8-1 -> 18 | X8: =+Y8-1 -> 19 | Y8: =+Z8-1 -> 20 | Z8: =+AA8-1 -> 21 | AA8: 22 | AB8: =IF(AA8="","",AA8+1) -> 23 | AC8: =IF(AB8="","",AB8+1) -> 24 | AD8: =IF(AC8="","",AC8+1) -> 25 | AE8: =IF(AD8="","",AD8+1) -> 26 | AF8: =IF(AE8="","",AE8+1) -> 27 | AG8: =IF(AF8="","",AF8+1) -> 28 | AH8: =IF(AG8="","",AG8+1) -> 29 | AI8: =IF(AH8="","",AH8+1) -> 30 | ... AL8: =IF(AK8="","",AK8+1) -> 33 | AM8: 0 | AN8: =IF(AM8="","",AM8+1) -> 1 | AO8: =IF(AN8="","",AN8+1) -> 2 | AP8: =IF(AO8="","",AO8+1) -> 3 | AQ8: =IF(AP8="","",AP8+1) -> 4 | AR8: =IF(AQ8="","",AQ8+1) -> 5 | AS8: =IF(AR8="","",AR8+1) -> 6 | AT8: =IF(AS8="","",AS8+1) -> 7 | AU8: =IF(AT8="","",AT8+1) -> 8 | ... BC8: =IF(BB8="","",BB8+1) -> 16 | BD8: 0 | BE8: =IF(BD8="","",BD8+1) -> 1 | BF8: =IF(BE8="","",BE8+1) -> 2 | BG8: =IF(BF8="","",BF8+1) -> 3 | BH8: =IF(BG8="","",BG8+1) -> 4 | BI8: =IF(BH8="","",BH8+1) -> 5 | BJ8: =IF(BI8="","",BI8+1) -> 6 | BK8: =IF(BJ8="","",BJ8+1) -> 7 | BL8: =IF(BK8="","",BK8+1) -> 8 | ... GX8: =IF(GW8="","",GW8+1) -> 150
A9: Vitis | B9: 1 | C9: El Cristal | D9: 8 | E9: El Cristal-8 | F9: Deli x La Me | G9: Irho | H9: 2009 | I9: 17 | J9: 61.86 | K9: 297 | L9: 8475 | M9: 8178 | N9: Family Capital | O9: Administrado | P9: Productivo | Q9: =IF(R9="","",'Dashboard Ciclos'!$B$2-R9) -> 46244 | R9: =IF($E9="","",IFERROR(INDEX($W9:$GX9,MATCH('Dashboard Ciclos'!$B$2,$W$1:$GX$1,0)),"")) -> 5 | S9: =IF($Q9="","Sin dato",IF($R9<=CicloObjetivo,"En ciclo",IF($R9-CicloObjetivo<=5,"Vencido 1-5 d",IF($R9-CicloObjetivo<=10,"Vencido 6-10 d",IF($R9-CicloObjetivo<=15,"Vencido 11-15 d","Vencido +15 d"))))) -> En ciclo | T9: =IF($Q9="","Sin dato",IF($R9<VentanaCosecha,"Recién cortado",IF($R9<=CicloObjetivo,"En ciclo","Fuera de ciclo"))) -> En ciclo | U9: =IF($Q9="","",CicloObjetivo-$R9) -> 7 | V9: =IF($Q9="","",$Q9+CicloObjetivo) -> 46256 | W9: =+X9-1 -> 18 | X9: =+Y9-1 -> 19 | Y9: =+Z9-1 -> 20 | Z9: =+AA9-1 -> 21 | AA9: 22 | AB9: =IF(AA9="","",AA9+1) -> 23 | AC9: =IF(AB9="","",AB9+1) -> 24 | AD9: =IF(AC9="","",AC9+1) -> 25 | AE9: =IF(AD9="","",AD9+1) -> 26 | AF9: =IF(AE9="","",AE9+1) -> 27 | AG9: =IF(AF9="","",AF9+1) -> 28 | AH9: =IF(AG9="","",AG9+1) -> 29 | AI9: =IF(AH9="","",AH9+1) -> 30 | ... AP9: =IF(AO9="","",AO9+1) -> 37 | AQ9: 0 | AR9: =IF(AQ9="","",AQ9+1) -> 1 | AS9: =IF(AR9="","",AR9+1) -> 2 | AT9: =IF(AS9="","",AS9+1) -> 3 | AU9: =IF(AT9="","",AT9+1) -> 4 | AV9: =IF(AU9="","",AU9+1) -> 5 | AW9: =IF(AV9="","",AV9+1) -> 6 | AX9: =IF(AW9="","",AW9+1) -> 7 | AY9: =IF(AX9="","",AX9+1) -> 8 | ... BJ9: =IF(BI9="","",BI9+1) -> 19 | BK9: 0 | BL9: =IF(BK9="","",BK9+1) -> 1 | BM9: =IF(BL9="","",BL9+1) -> 2 | BN9: =IF(BM9="","",BM9+1) -> 3 | BO9: =IF(BN9="","",BN9+1) -> 4 | BP9: =IF(BO9="","",BO9+1) -> 5 | BQ9: =IF(BP9="","",BP9+1) -> 6 | BR9: =IF(BQ9="","",BQ9+1) -> 7 | BS9: =IF(BR9="","",BR9+1) -> 8 | ... GX9: =IF(GW9="","",GW9+1) -> 143
A10: Vitis | B10: 1 | C10: El Cristal | D10: 9 | E10: El Cristal-9 | F10: Deli x La Me | G10: Irho | H10: 2009 | I10: 17 | J10: 46.31 | K10: 0 | L10: 6536 | M10: 6536 | N10: Family Capital | O10: Administrado | P10: Productivo | Q10: =IF(R10="","",'Dashboard Ciclos'!$B$2-R10) -> 46245 | R10: =IF($E10="","",IFERROR(INDEX($W10:$GX10,MATCH('Dashboard Ciclos'!$B$2,$W$1:$GX$1,0)),"")) -> 4 | S10: =IF($Q10="","Sin dato",IF($R10<=CicloObjetivo,"En ciclo",IF($R10-CicloObjetivo<=5,"Vencido 1-5 d",IF($R10-CicloObjetivo<=10,"Vencido 6-10 d",IF($R10-CicloObjetivo<=15,"Vencido 11-15 d","Vencido +15 d"))))) -> En ciclo | T10: =IF($Q10="","Sin dato",IF($R10<VentanaCosecha,"Recién cortado",IF($R10<=CicloObjetivo,"En ciclo","Fuera de ciclo"))) -> Recién cortado | U10: =IF($Q10="","",CicloObjetivo-$R10) -> 8 | V10: =IF($Q10="","",$Q10+CicloObjetivo) -> 46257 | W10: =+X10-1 -> 14 | X10: =+Y10-1 -> 15 | Y10: =+Z10-1 -> 16 | Z10: =+AA10-1 -> 17 | AA10: 18 | AB10: =IF(AA10="","",AA10+1) -> 19 | AC10: =IF(AB10="","",AB10+1) -> 20 | AD10: =IF(AC10="","",AC10+1) -> 21 | AE10: =IF(AD10="","",AD10+1) -> 22 | AF10: =IF(AE10="","",AE10+1) -> 23 | AG10: =IF(AF10="","",AF10+1) -> 24 | AH10: =IF(AG10="","",AG10+1) -> 25 | AI10: =IF(AH10="","",AH10+1) -> 26 | ... AQ10: =IF(AP10="","",AP10+1) -> 34 | AR10: 0 | AS10: =IF(AR10="","",AR10+1) -> 1 | AT10: =IF(AS10="","",AS10+1) -> 2 | AU10: =IF(AT10="","",AT10+1) -> 3 | AV10: =IF(AU10="","",AU10+1) -> 4 | AW10: =IF(AV10="","",AV10+1) -> 5 | AX10: =IF(AW10="","",AW10+1) -> 6 | AY10: =IF(AX10="","",AX10+1) -> 7 | AZ10: =IF(AY10="","",AY10+1) -> 8 | ... BK10: =IF(BJ10="","",BJ10+1) -> 19 | BL10: 0 | BM10: =IF(BL10="","",BL10+1) -> 1 | BN10: =IF(BM10="","",BM10+1) -> 2 | BO10: =IF(BN10="","",BN10+1) -> 3 | BP10: =IF(BO10="","",BO10+1) -> 4 | BQ10: =IF(BP10="","",BP10+1) -> 5 | BR10: =IF(BQ10="","",BQ10+1) -> 6 | BS10: =IF(BR10="","",BR10+1) -> 7 | BT10: =IF(BS10="","",BS10+1) -> 8 | ... GX10: =IF(GW10="","",GW10+1) -> 142
A11: Vitis | B11: 1 | C11: El Cristal | D11: 10 | E11: El Cristal-10 | F11: Deli x La Me | G11: Irho | H11: 2009 | I11: 17 | J11: 50.1 | K11: 207 | L11: 7081 | M11: 6874 | N11: Family Capital | O11: Administrado | P11: Productivo | Q11: =IF(R11="","",'Dashboard Ciclos'!$B$2-R11) -> 46246 | R11: =IF($E11="","",IFERROR(INDEX($W11:$GX11,MATCH('Dashboard Ciclos'!$B$2,$W$1:$GX$1,0)),"")) -> 3 | S11: =IF($Q11="","Sin dato",IF($R11<=CicloObjetivo,"En ciclo",IF($R11-CicloObjetivo<=5,"Vencido 1-5 d",IF($R11-CicloObjetivo<=10,"Vencido 6-10 d",IF($R11-CicloObjetivo<=15,"Vencido 11-15 d","Vencido +15 d"))))) -> En ciclo | T11: =IF($Q11="","Sin dato",IF($R11<VentanaCosecha,"Recién cortado",IF($R11<=CicloObjetivo,"En ciclo","Fuera de ciclo"))) -> Recién cortado | U11: =IF($Q11="","",CicloObjetivo-$R11) -> 9 | V11: =IF($Q11="","",$Q11+CicloObjetivo) -> 46258 | W11: =+X11-1 -> 11 | X11: =+Y11-1 -> 12 | Y11: =+Z11-1 -> 13 | Z11: =+AA11-1 -> 14 | AA11: 15 | AB11: =IF(AA11="","",AA11+1) -> 16 | AC11: =IF(AB11="","",AB11+1) -> 17 | AD11: =IF(AC11="","",AC11+1) -> 18 | AE11: =IF(AD11="","",AD11+1) -> 19 | AF11: =IF(AE11="","",AE11+1) -> 20 | AG11: =IF(AF11="","",AF11+1) -> 21 | AH11: =IF(AG11="","",AG11+1) -> 22 | AI11: =IF(AH11="","",AH11+1) -> 23 | ... AR11: =IF(AQ11="","",AQ11+1) -> 32 | AS11: 0 | AT11: =IF(AS11="","",AS11+1) -> 1 | AU11: =IF(AT11="","",AT11+1) -> 2 | AV11: =IF(AU11="","",AU11+1) -> 3 | AW11: =IF(AV11="","",AV11+1) -> 4 | AX11: =IF(AW11="","",AW11+1) -> 5 | AY11: =IF(AX11="","",AX11+1) -> 6 | AZ11: =IF(AY11="","",AY11+1) -> 7 | BA11: =IF(AZ11="","",AZ11+1) -> 8 | ... BL11: =IF(BK11="","",BK11+1) -> 19 | BM11: 0 | BN11: =IF(BM11="","",BM11+1) -> 1 | BO11: =IF(BN11="","",BN11+1) -> 2 | BP11: =IF(BO11="","",BO11+1) -> 3 | BQ11: =IF(BP11="","",BP11+1) -> 4 | BR11: =IF(BQ11="","",BQ11+1) -> 5 | BS11: =IF(BR11="","",BR11+1) -> 6 | BT11: =IF(BS11="","",BS11+1) -> 7 | BU11: =IF(BT11="","",BT11+1) -> 8 | ... GX11: =IF(GW11="","",GW11+1) -> 141
A12: Vitis | B12: 1 | C12: El Cristal | D12: 11 | E12: El Cristal-11 | F12: Deli x La Me | G12: Irho | H12: 2009 | I12: 17 | J12: 36.5 | K12: 145 | L12: 5172 | M12: 5027 | N12: Family Capital | O12: Administrado | P12: Productivo | Q12: =IF(R12="","",'Dashboard Ciclos'!$B$2-R12) -> 46248 | R12: =IF($E12="","",IFERROR(INDEX($W12:$GX12,MATCH('Dashboard Ciclos'!$B$2,$W$1:$GX$1,0)),"")) -> 1 | S12: =IF($Q12="","Sin dato",IF($R12<=CicloObjetivo,"En ciclo",IF($R12-CicloObjetivo<=5,"Vencido 1-5 d",IF($R12-CicloObjetivo<=10,"Vencido 6-10 d",IF($R12-CicloObjetivo<=15,"Vencido 11-15 d","Vencido +15 d"))))) -> En ciclo | T12: =IF($Q12="","Sin dato",IF($R12<VentanaCosecha,"Recién cortado",IF($R12<=CicloObjetivo,"En ciclo","Fuera de ciclo"))) -> Recién cortado | U12: =IF($Q12="","",CicloObjetivo-$R12) -> 11 | V12: =IF($Q12="","",$Q12+CicloObjetivo) -> 46260 | W12: =+X12-1 -> 8 | X12: =+Y12-1 -> 9 | Y12: =+Z12-1 -> 10 | Z12: =+AA12-1 -> 11 | AA12: 12 | AB12: =IF(AA12="","",AA12+1) -> 13 | AC12: =IF(AB12="","",AB12+1) -> 14 | AD12: =IF(AC12="","",AC12+1) -> 15 | AE12: =IF(AD12="","",AD12+1) -> 16 | AF12: =IF(AE12="","",AE12+1) -> 17 | AG12: =IF(AF12="","",AF12+1) -> 18 | AH12: =IF(AG12="","",AG12+1) -> 19 | AI12: =IF(AH12="","",AH12+1) -> 20 | ... AT12: =IF(AS12="","",AS12+1) -> 31 | AU12: 0 | AV12: =IF(AU12="","",AU12+1) -> 1 | AW12: =IF(AV12="","",AV12+1) -> 2 | AX12: =IF(AW12="","",AW12+1) -> 3 | AY12: =IF(AX12="","",AX12+1) -> 4 | AZ12: =IF(AY12="","",AY12+1) -> 5 | BA12: =IF(AZ12="","",AZ12+1) -> 6 | BB12: =IF(BA12="","",BA12+1) -> 7 | BC12: =IF(BB12="","",BB12+1) -> 8 | ... BN12: =IF(BM12="","",BM12+1) -> 19 | BO12: 0 | BP12: =IF(BO12="","",BO12+1) -> 1 | BQ12: =IF(BP12="","",BP12+1) -> 2 | BR12: =IF(BQ12="","",BQ12+1) -> 3 | BS12: =IF(BR12="","",BR12+1) -> 4 | BT12: =IF(BS12="","",BS12+1) -> 5 | BU12: =IF(BT12="","",BT12+1) -> 6 | BV12: =IF(BU12="","",BU12+1) -> 7 | BW12: =IF(BV12="","",BV12+1) -> 8 | ... GX12: =IF(GW12="","",GW12+1) -> 139
A13: Vitis | B13: 1 | C13: El Cristal | D13: 12 | E13: El Cristal-12 | F13: Deli x La Me | G13: Irho | H13: 2009 | I13: 17 | J13: 18.89 | K13: 0 | L13: 2664 | M13: 2664 | N13: Family Capital | O13: Administrado | P13: Productivo | Q13: =IF(R13="","",'Dashboard Ciclos'!$B$2-R13) -> 46230 | R13: =IF($E13="","",IFERROR(INDEX($W13:$GX13,MATCH('Dashboard Ciclos'!$B$2,$W$1:$GX$1,0)),"")) -> 19 | S13: =IF($Q13="","Sin dato",IF($R13<=CicloObjetivo,"En ciclo",IF($R13-CicloObjetivo<=5,"Vencido 1-5 d",IF($R13-CicloObjetivo<=10,"Vencido 6-10 d",IF($R13-CicloObjetivo<=15,"Vencido 11-15 d","Vencido +15 d"))))) -> Vencido 6-10 d | T13: =IF($Q13="","Sin dato",IF($R13<VentanaCosecha,"Recién cortado",IF($R13<=CicloObjetivo,"En ciclo","Fuera de ciclo"))) -> Fuera de ciclo | U13: =IF($Q13="","",CicloObjetivo-$R13) -> -7 | V13: =IF($Q13="","",$Q13+CicloObjetivo) -> 46242 | W13: =+X13-1 -> 5 | X13: =+Y13-1 -> 6 | Y13: =+Z13-1 -> 7 | Z13: =+AA13-1 -> 8 | AA13: 9 | AB13: =IF(AA13="","",AA13+1) -> 10 | AC13: =IF(AB13="","",AB13+1) -> 11 | AD13: =IF(AC13="","",AC13+1) -> 12 | AE13: =IF(AD13="","",AD13+1) -> 13 | AF13: =IF(AE13="","",AE13+1) -> 14 | AG13: =IF(AF13="","",AF13+1) -> 15 | AH13: =IF(AG13="","",AG13+1) -> 16 | AI13: =IF(AH13="","",AH13+1) -> 17 | ... AV13: =IF(AU13="","",AU13+1) -> 30 | AW13: 0 | AX13: =IF(AW13="","",AW13+1) -> 1 | AY13: =IF(AX13="","",AX13+1) -> 2 | AZ13: =IF(AY13="","",AY13+1) -> 3 | BA13: =IF(AZ13="","",AZ13+1) -> 4 | BB13: =IF(BA13="","",BA13+1) -> 5 | BC13: =IF(BB13="","",BB13+1) -> 6 | BD13: =IF(BC13="","",BC13+1) -> 7 | BE13: =IF(BD13="","",BD13+1) -> 8 | ... GX13: =IF(GW13="","",GW13+1) -> 157
A14: Vitis | B14: 1 | C14: El Cristal | D14: 13 | E14: El Cristal-13 | F14: Deli x La Me | G14: Irho | H14: 2009 | I14: 17 | J14: 46.26 | K14: 51 | L14: 6551 | M14: 6500 | N14: Family Capital | O14: Administrado | P14: Productivo | Q14: =IF(R14="","",'Dashboard Ciclos'!$B$2-R14) -> 46230 | R14: =IF($E14="","",IFERROR(INDEX($W14:$GX14,MATCH('Dashboard Ciclos'!$B$2,$W$1:$GX$1,0)),"")) -> 19 | S14: =IF($Q14="","Sin dato",IF($R14<=CicloObjetivo,"En ciclo",IF($R14-CicloObjetivo<=5,"Vencido 1-5 d",IF($R14-CicloObjetivo<=10,"Vencido 6-10 d",IF($R14-CicloObjetivo<=15,"Vencido 11-15 d","Vencido +15 d"))))) -> Vencido 6-10 d | T14: =IF($Q14="","Sin dato",IF($R14<VentanaCosecha,"Recién cortado",IF($R14<=CicloObjetivo,"En ciclo","Fuera de ciclo"))) -> Fuera de ciclo | U14: =IF($Q14="","",CicloObjetivo-$R14) -> -7 | V14: =IF($Q14="","",$Q14+CicloObjetivo) -> 46242 | W14: =+X14-1 -> 2 | X14: =+Y14-1 -> 3 | Y14: =+Z14-1 -> 4 | Z14: =+AA14-1 -> 5 | AA14: 6 | AB14: =IF(AA14="","",AA14+1) -> 7 | AC14: =IF(AB14="","",AB14+1) -> 8 | AD14: =IF(AC14="","",AC14+1) -> 9 | AE14: =IF(AD14="","",AD14+1) -> 10 | AF14: =IF(AE14="","",AE14+1) -> 11 | AG14: =IF(AF14="","",AF14+1) -> 12 | AH14: =IF(AG14="","",AG14+1) -> 13 | AI14: =IF(AH14="","",AH14+1) -> 14 | ... AV14: =IF(AU14="","",AU14+1) -> 27 | AW14: 0 | AX14: =IF(AW14="","",AW14+1) -> 1 | AY14: =IF(AX14="","",AX14+1) -> 2 | AZ14: =IF(AY14="","",AY14+1) -> 3 | BA14: =IF(AZ14="","",AZ14+1) -> 4 | BB14: =IF(BA14="","",BA14+1) -> 5 | BC14: =IF(BB14="","",BB14+1) -> 6 | BD14: =IF(BC14="","",BC14+1) -> 7 | BE14: =IF(BD14="","",BD14+1) -> 8 | ... GX14: =IF(GW14="","",GW14+1) -> 157
A15: Vitis | B15: 2 | C15: La Bendición | D15: 14 | E15: La Bendición-14 | F15: Deli x La Me | G15: Irho | H15: 2009 | I15: 17 | J15: 45.18 | K15: 61 | L15: 6215 | M15: 6154 | N15: Vitis Olei | O15: Propio | P15: Productivo | Q15: =IF(R15="","",'Dashboard Ciclos'!$B$2-R15) -> 46239 | R15: =IF($E15="","",IFERROR(INDEX($W15:$GX15,MATCH('Dashboard Ciclos'!$B$2,$W$1:$GX$1,0)),"")) -> 10 | S15: =IF($Q15="","Sin dato",IF($R15<=CicloObjetivo,"En ciclo",IF($R15-CicloObjetivo<=5,"Vencido 1-5 d",IF($R15-CicloObjetivo<=10,"Vencido 6-10 d",IF($R15-CicloObjetivo<=15,"Vencido 11-15 d","Vencido +15 d"))))) -> En ciclo | T15: =IF($Q15="","Sin dato",IF($R15<VentanaCosecha,"Recién cortado",IF($R15<=CicloObjetivo,"En ciclo","Fuera de ciclo"))) -> En ciclo | U15: =IF($Q15="","",CicloObjetivo-$R15) -> 2 | V15: =IF($Q15="","",$Q15+CicloObjetivo) -> 46251 | W15: =+X15-1 -> 13 | X15: =+Y15-1 -> 14 | Y15: =+Z15-1 -> 15 | Z15: =+AA15-1 -> 16 | AA15: 17 | AB15: =IF(AA15="","",AA15+1) -> 18 | AC15: =IF(AB15="","",AB15+1) -> 19 | AD15: =IF(AC15="","",AC15+1) -> 20 | AE15: =IF(AD15="","",AD15+1) -> 21 | AF15: =IF(AE15="","",AE15+1) -> 22 | AG15: =IF(AF15="","",AF15+1) -> 23 | AH15: =IF(AG15="","",AG15+1) -> 24 | AI15: =IF(AH15="","",AH15+1) -> 25 | ... AQ15: =IF(AP15="","",AP15+1) -> 33 | AR15: 0 | AS15: =IF(AR15="","",AR15+1) -> 1 | AT15: =IF(AS15="","",AS15+1) -> 2 | AU15: =IF(AT15="","",AT15+1) -> 3 | AV15: =IF(AU15="","",AU15+1) -> 4 | AW15: =IF(AV15="","",AV15+1) -> 5 | AX15: =IF(AW15="","",AW15+1) -> 6 | AY15: =IF(AX15="","",AX15+1) -> 7 | AZ15: =IF(AY15="","",AY15+1) -> 8 | ... BE15: =IF(BD15="","",BD15+1) -> 13 | BF15: 0 | BG15: =IF(BF15="","",BF15+1) -> 1 | BH15: =IF(BG15="","",BG15+1) -> 2 | BI15: =IF(BH15="","",BH15+1) -> 3 | BJ15: =IF(BI15="","",BI15+1) -> 4 | BK15: =IF(BJ15="","",BJ15+1) -> 5 | BL15: =IF(BK15="","",BK15+1) -> 6 | BM15: =IF(BL15="","",BL15+1) -> 7 | BN15: =IF(BM15="","",BM15+1) -> 8 | ... GX15: =IF(GW15="","",GW15+1) -> 148
A16: Vitis | B16: 2 | C16: La Bendición | D16: 15 | E16: La Bendición-15 | F16: Deli x Mezcla | G16: Mezcla | H16: 2009 | I16: 17 | J16: 39.98 | K16: 107 | L16: 5352 | M16: 5245 | N16: Vitis Olei | O16: Propio | P16: Productivo | Q16: =IF(R16="","",'Dashboard Ciclos'!$B$2-R16) -> 46239 | R16: =IF($E16="","",IFERROR(INDEX($W16:$GX16,MATCH('Dashboard Ciclos'!$B$2,$W$1:$GX$1,0)),"")) -> 10 | S16: =IF($Q16="","Sin dato",IF($R16<=CicloObjetivo,"En ciclo",IF($R16-CicloObjetivo<=5,"Vencido 1-5 d",IF($R16-CicloObjetivo<=10,"Vencido 6-10 d",IF($R16-CicloObjetivo<=15,"Vencido 11-15 d","Vencido +15 d"))))) -> En ciclo | T16: =IF($Q16="","Sin dato",IF($R16<VentanaCosecha,"Recién cortado",IF($R16<=CicloObjetivo,"En ciclo","Fuera de ciclo"))) -> En ciclo | U16: =IF($Q16="","",CicloObjetivo-$R16) -> 2 | V16: =IF($Q16="","",$Q16+CicloObjetivo) -> 46251 | W16: =+X16-1 -> 14 | X16: =+Y16-1 -> 15 | Y16: =+Z16-1 -> 16 | Z16: =+AA16-1 -> 17 | AA16: 18 | AB16: =IF(AA16="","",AA16+1) -> 19 | AC16: =IF(AB16="","",AB16+1) -> 20 | AD16: =IF(AC16="","",AC16+1) -> 21 | AE16: =IF(AD16="","",AD16+1) -> 22 | AF16: =IF(AE16="","",AE16+1) -> 23 | AG16: =IF(AF16="","",AF16+1) -> 24 | AH16: =IF(AG16="","",AG16+1) -> 25 | AI16: =IF(AH16="","",AH16+1) -> 26 | ... AQ16: =IF(AP16="","",AP16+1) -> 34 | AR16: 0 | AS16: =IF(AR16="","",AR16+1) -> 1 | AT16: =IF(AS16="","",AS16+1) -> 2 | AU16: =IF(AT16="","",AT16+1) -> 3 | AV16: =IF(AU16="","",AU16+1) -> 4 | AW16: =IF(AV16="","",AV16+1) -> 5 | AX16: =IF(AW16="","",AW16+1) -> 6 | AY16: =IF(AX16="","",AX16+1) -> 7 | AZ16: =IF(AY16="","",AY16+1) -> 8 | ... BE16: =IF(BD16="","",BD16+1) -> 13 | BF16: 0 | BG16: =IF(BF16="","",BF16+1) -> 1 | BH16: =IF(BG16="","",BG16+1) -> 2 | BI16: =IF(BH16="","",BH16+1) -> 3 | BJ16: =IF(BI16="","",BI16+1) -> 4 | BK16: =IF(BJ16="","",BJ16+1) -> 5 | BL16: =IF(BK16="","",BK16+1) -> 6 | BM16: =IF(BL16="","",BL16+1) -> 7 | BN16: =IF(BM16="","",BM16+1) -> 8 | ... GX16: =IF(GW16="","",GW16+1) -> 148
A17: Vitis | B17: 2 | C17: La Bendición | D17: 16 | E17: La Bendición-16 | F17: Deli x La Me | G17: Irho | H17: 2009 | I17: 17 | J17: 13.11 | K17: 32 | L17: 1803 | M17: 1771 | N17: Vitis Olei | O17: Propio | P17: Productivo | Q17: =IF(R17="","",'Dashboard Ciclos'!$B$2-R17) -> 46239 | R17: =IF($E17="","",IFERROR(INDEX($W17:$GX17,MATCH('Dashboard Ciclos'!$B$2,$W$1:$GX$1,0)),"")) -> 10 | S17: =IF($Q17="","Sin dato",IF($R17<=CicloObjetivo,"En ciclo",IF($R17-CicloObjetivo<=5,"Vencido 1-5 d",IF($R17-CicloObjetivo<=10,"Vencido 6-10 d",IF($R17-CicloObjetivo<=15,"Vencido 11-15 d","Vencido +15 d"))))) -> En ciclo | T17: =IF($Q17="","Sin dato",IF($R17<VentanaCosecha,"Recién cortado",IF($R17<=CicloObjetivo,"En ciclo","Fuera de ciclo"))) -> En ciclo | U17: =IF($Q17="","",CicloObjetivo-$R17) -> 2 | V17: =IF($Q17="","",$Q17+CicloObjetivo) -> 46251 | W17: =+X17-1 -> 14 | X17: =+Y17-1 -> 15 | Y17: =+Z17-1 -> 16 | Z17: =+AA17-1 -> 17 | AA17: 18 | AB17: =IF(AA17="","",AA17+1) -> 19 | AC17: =IF(AB17="","",AB17+1) -> 20 | AD17: =IF(AC17="","",AC17+1) -> 21 | AE17: =IF(AD17="","",AD17+1) -> 22 | AF17: =IF(AE17="","",AE17+1) -> 23 | AG17: =IF(AF17="","",AF17+1) -> 24 | AH17: =IF(AG17="","",AG17+1) -> 25 | AI17: =IF(AH17="","",AH17+1) -> 26 | ... AO17: =IF(AN17="","",AN17+1) -> 32 | AP17: 0 | AQ17: =IF(AP17="","",AP17+1) -> 1 | AR17: =IF(AQ17="","",AQ17+1) -> 2 | AS17: =IF(AR17="","",AR17+1) -> 3 | AT17: =IF(AS17="","",AS17+1) -> 4 | AU17: =IF(AT17="","",AT17+1) -> 5 | AV17: =IF(AU17="","",AU17+1) -> 6 | AW17: =IF(AV17="","",AV17+1) -> 7 | AX17: =IF(AW17="","",AW17+1) -> 8 | ... BE17: =IF(BD17="","",BD17+1) -> 15 | BF17: 0 | BG17: =IF(BF17="","",BF17+1) -> 1 | BH17: =IF(BG17="","",BG17+1) -> 2 | BI17: =IF(BH17="","",BH17+1) -> 3 | BJ17: =IF(BI17="","",BI17+1) -> 4 | BK17: =IF(BJ17="","",BJ17+1) -> 5 | BL17: =IF(BK17="","",BK17+1) -> 6 | BM17: =IF(BL17="","",BL17+1) -> 7 | BN17: =IF(BM17="","",BM17+1) -> 8 | ... GX17: =IF(GW17="","",GW17+1) -> 148
A18: Vitis | B18: 2 | C18: La Bendición | D18: 17 | E18: La Bendición-17 | F18: Deli x La Me | G18: Irho | H18: 2009 | I18: 17 | J18: 27.44 | K18: 152 | L18: 3745 | M18: 3593 | N18: Vitis Olei | O18: Propio | P18: Productivo | Q18: =IF(R18="","",'Dashboard Ciclos'!$B$2-R18) -> 46238 | R18: =IF($E18="","",IFERROR(INDEX($W18:$GX18,MATCH('Dashboard Ciclos'!$B$2,$W$1:$GX$1,0)),"")) -> 11 | S18: =IF($Q18="","Sin dato",IF($R18<=CicloObjetivo,"En ciclo",IF($R18-CicloObjetivo<=5,"Vencido 1-5 d",IF($R18-CicloObjetivo<=10,"Vencido 6-10 d",IF($R18-CicloObjetivo<=15,"Vencido 11-15 d","Vencido +15 d"))))) -> En ciclo | T18: =IF($Q18="","Sin dato",IF($R18<VentanaCosecha,"Recién cortado",IF($R18<=CicloObjetivo,"En ciclo","Fuera de ciclo"))) -> En ciclo | U18: =IF($Q18="","",CicloObjetivo-$R18) -> 1 | V18: =IF($Q18="","",$Q18+CicloObjetivo) -> 46250 | W18: =+X18-1 -> 18 | X18: =+Y18-1 -> 19 | Y18: =+Z18-1 -> 20 | Z18: =+AA18-1 -> 21 | AA18: 22 | AB18: =IF(AA18="","",AA18+1) -> 23 | AC18: =IF(AB18="","",AB18+1) -> 24 | AD18: =IF(AC18="","",AC18+1) -> 25 | AE18: =IF(AD18="","",AD18+1) -> 26 | AF18: =IF(AE18="","",AE18+1) -> 27 | AG18: =IF(AF18="","",AF18+1) -> 28 | AH18: =IF(AG18="","",AG18+1) -> 29 | AI18: =IF(AH18="","",AH18+1) -> 30 | ... AM18: =IF(AL18="","",AL18+1) -> 34 | AN18: 0 | AO18: =IF(AN18="","",AN18+1) -> 1 | AP18: =IF(AO18="","",AO18+1) -> 2 | AQ18: =IF(AP18="","",AP18+1) -> 3 | AR18: =IF(AQ18="","",AQ18+1) -> 4 | AS18: =IF(AR18="","",AR18+1) -> 5 | AT18: =IF(AS18="","",AS18+1) -> 6 | AU18: =IF(AT18="","",AT18+1) -> 7 | AV18: =IF(AU18="","",AU18+1) -> 8 | ... BD18: =IF(BC18="","",BC18+1) -> 16 | BE18: 0 | BF18: =IF(BE18="","",BE18+1) -> 1 | BG18: =IF(BF18="","",BF18+1) -> 2 | BH18: =IF(BG18="","",BG18+1) -> 3 | BI18: =IF(BH18="","",BH18+1) -> 4 | BJ18: =IF(BI18="","",BI18+1) -> 5 | BK18: =IF(BJ18="","",BJ18+1) -> 6 | BL18: =IF(BK18="","",BK18+1) -> 7 | BM18: =IF(BL18="","",BL18+1) -> 8 | ... GX18: =IF(GW18="","",GW18+1) -> 149
A19: Vitis | B19: 3 | C19: La Bendición | D19: 18 | E19: La Bendición-18 | F19: Deli x Mezcla | G19: Mezcla | H19: 2009 | I19: 17 | J19: 17.58 | K19: 130 | L19: 2330 | M19: 2200 | N19: Vitis Olei | O19: Propio | P19: Productivo | Q19: =IF(R19="","",'Dashboard Ciclos'!$B$2-R19) -> 46238 | R19: =IF($E19="","",IFERROR(INDEX($W19:$GX19,MATCH('Dashboard Ciclos'!$B$2,$W$1:$GX$1,0)),"")) -> 11 | S19: =IF($Q19="","Sin dato",IF($R19<=CicloObjetivo,"En ciclo",IF($R19-CicloObjetivo<=5,"Vencido 1-5 d",IF($R19-CicloObjetivo<=10,"Vencido 6-10 d",IF($R19-CicloObjetivo<=15,"Vencido 11-15 d","Vencido +15 d"))))) -> En ciclo | T19: =IF($Q19="","Sin dato",IF($R19<VentanaCosecha,"Recién cortado",IF($R19<=CicloObjetivo,"En ciclo","Fuera de ciclo"))) -> En ciclo | U19: =IF($Q19="","",CicloObjetivo-$R19) -> 1 | V19: =IF($Q19="","",$Q19+CicloObjetivo) -> 46250 | W19: =+X19-1 -> 6 | X19: =+Y19-1 -> 7 | Y19: =+Z19-1 -> 8 | Z19: =+AA19-1 -> 9 | AA19: 10 | AB19: =IF(AA19="","",AA19+1) -> 11 | AC19: =IF(AB19="","",AB19+1) -> 12 | AD19: =IF(AC19="","",AC19+1) -> 13 | AE19: =IF(AD19="","",AD19+1) -> 14 | AF19: =IF(AE19="","",AE19+1) -> 15 | AG19: =IF(AF19="","",AF19+1) -> 16 | AH19: =IF(AG19="","",AG19+1) -> 17 | AI19: =IF(AH19="","",AH19+1) -> 18 | AJ19: 0 | AK19: =IF(AJ19="","",AJ19+1) -> 1 | AL19: =IF(AK19="","",AK19+1) -> 2 | AM19: =IF(AL19="","",AL19+1) -> 3 | AN19: =IF(AM19="","",AM19+1) -> 4 | AO19: =IF(AN19="","",AN19+1) -> 5 | AP19: =IF(AO19="","",AO19+1) -> 6 | AQ19: =IF(AP19="","",AP19+1) -> 7 | AR19: =IF(AQ19="","",AQ19+1) -> 8 | ... BD19: =IF(BC19="","",BC19+1) -> 20 | BE19: 0 | BF19: =IF(BE19="","",BE19+1) -> 1 | BG19: =IF(BF19="","",BF19+1) -> 2 | BH19: =IF(BG19="","",BG19+1) -> 3 | BI19: =IF(BH19="","",BH19+1) -> 4 | BJ19: =IF(BI19="","",BI19+1) -> 5 | BK19: =IF(BJ19="","",BJ19+1) -> 6 | BL19: =IF(BK19="","",BK19+1) -> 7 | BM19: =IF(BL19="","",BL19+1) -> 8 | ... GX19: =IF(GW19="","",GW19+1) -> 149
A20: Vitis | B20: 2 | C20: La Bendición | D20: 19 | E20: La Bendición-19 | F20: Deli x Nigeria | G20: Asd | H20: 2009 | I20: 17 | J20: 36.26 | K20: 0 | L20: 4474 | M20: 4474 | N20: Vitis Olei | O20: Propio | P20: Productivo | Q20: =IF(R20="","",'Dashboard Ciclos'!$B$2-R20) -> 46240 | R20: =IF($E20="","",IFERROR(INDEX($W20:$GX20,MATCH('Dashboard Ciclos'!$B$2,$W$1:$GX$1,0)),"")) -> 9 | S20: =IF($Q20="","Sin dato",IF($R20<=CicloObjetivo,"En ciclo",IF($R20-CicloObjetivo<=5,"Vencido 1-5 d",IF($R20-CicloObjetivo<=10,"Vencido 6-10 d",IF($R20-CicloObjetivo<=15,"Vencido 11-15 d","Vencido +15 d"))))) -> En ciclo | T20: =IF($Q20="","Sin dato",IF($R20<VentanaCosecha,"Recién cortado",IF($R20<=CicloObjetivo,"En ciclo","Fuera de ciclo"))) -> En ciclo | U20: =IF($Q20="","",CicloObjetivo-$R20) -> 3 | V20: =IF($Q20="","",$Q20+CicloObjetivo) -> 46252 | W20: =+X20-1 -> 12 | X20: =+Y20-1 -> 13 | Y20: =+Z20-1 -> 14 | Z20: =+AA20-1 -> 15 | AA20: 16 | AB20: =IF(AA20="","",AA20+1) -> 17 | AC20: =IF(AB20="","",AB20+1) -> 18 | AD20: =IF(AC20="","",AC20+1) -> 19 | AE20: =IF(AD20="","",AD20+1) -> 20 | AF20: =IF(AE20="","",AE20+1) -> 21 | AG20: =IF(AF20="","",AF20+1) -> 22 | AH20: =IF(AG20="","",AG20+1) -> 23 | AI20: =IF(AH20="","",AH20+1) -> 24 | ... AR20: =IF(AQ20="","",AQ20+1) -> 33 | AS20: 0 | AT20: =IF(AS20="","",AS20+1) -> 1 | AU20: =IF(AT20="","",AT20+1) -> 2 | AV20: =IF(AU20="","",AU20+1) -> 3 | AW20: =IF(AV20="","",AV20+1) -> 4 | AX20: =IF(AW20="","",AW20+1) -> 5 | AY20: =IF(AX20="","",AX20+1) -> 6 | AZ20: =IF(AY20="","",AY20+1) -> 7 | BA20: =IF(AZ20="","",AZ20+1) -> 8 | ... BF20: =IF(BE20="","",BE20+1) -> 13 | BG20: 0 | BH20: =IF(BG20="","",BG20+1) -> 1 | BI20: =IF(BH20="","",BH20+1) -> 2 | BJ20: =IF(BI20="","",BI20+1) -> 3 | BK20: =IF(BJ20="","",BJ20+1) -> 4 | BL20: =IF(BK20="","",BK20+1) -> 5 | BM20: =IF(BL20="","",BL20+1) -> 6 | BN20: =IF(BM20="","",BM20+1) -> 7 | BO20: =IF(BN20="","",BN20+1) -> 8 | ... GX20: =IF(GW20="","",GW20+1) -> 147
A21: Vitis | B21: 2 | C21: Los Cambulos | D21: 20 | E21: Los Cambulos-20 | F21: Deli x La Me | G21: Irho | H21: 2009 | I21: 17 | J21: 23.43 | K21: 0 | L21: 3327 | M21: 3327 | N21: Vitis Olei | O21: Propio | P21: Productivo | Q21: =IF(R21="","",'Dashboard Ciclos'!$B$2-R21) -> 46240 | R21: =IF($E21="","",IFERROR(INDEX($W21:$GX21,MATCH('Dashboard Ciclos'!$B$2,$W$1:$GX$1,0)),"")) -> 9 | S21: =IF($Q21="","Sin dato",IF($R21<=CicloObjetivo,"En ciclo",IF($R21-CicloObjetivo<=5,"Vencido 1-5 d",IF($R21-CicloObjetivo<=10,"Vencido 6-10 d",IF($R21-CicloObjetivo<=15,"Vencido 11-15 d","Vencido +15 d"))))) -> En ciclo | T21: =IF($Q21="","Sin dato",IF($R21<VentanaCosecha,"Recién cortado",IF($R21<=CicloObjetivo,"En ciclo","Fuera de ciclo"))) -> En ciclo | U21: =IF($Q21="","",CicloObjetivo-$R21) -> 3 | V21: =IF($Q21="","",$Q21+CicloObjetivo) -> 46252 | W21: =+X21-1 -> 12 | X21: =+Y21-1 -> 13 | Y21: =+Z21-1 -> 14 | Z21: =+AA21-1 -> 15 | AA21: 16 | AB21: =IF(AA21="","",AA21+1) -> 17 | AC21: =IF(AB21="","",AB21+1) -> 18 | AD21: =IF(AC21="","",AC21+1) -> 19 | AE21: =IF(AD21="","",AD21+1) -> 20 | AF21: =IF(AE21="","",AE21+1) -> 21 | AG21: =IF(AF21="","",AF21+1) -> 22 | AH21: =IF(AG21="","",AG21+1) -> 23 | AI21: =IF(AH21="","",AH21+1) -> 24 | ... AR21: =IF(AQ21="","",AQ21+1) -> 33 | AS21: 0 | AT21: =IF(AS21="","",AS21+1) -> 1 | AU21: =IF(AT21="","",AT21+1) -> 2 | AV21: =IF(AU21="","",AU21+1) -> 3 | AW21: =IF(AV21="","",AV21+1) -> 4 | AX21: =IF(AW21="","",AW21+1) -> 5 | AY21: =IF(AX21="","",AX21+1) -> 6 | AZ21: =IF(AY21="","",AY21+1) -> 7 | BA21: =IF(AZ21="","",AZ21+1) -> 8 | ... BF21: =IF(BE21="","",BE21+1) -> 13 | BG21: 0 | BH21: =IF(BG21="","",BG21+1) -> 1 | BI21: =IF(BH21="","",BH21+1) -> 2 | BJ21: =IF(BI21="","",BI21+1) -> 3 | BK21: =IF(BJ21="","",BJ21+1) -> 4 | BL21: =IF(BK21="","",BK21+1) -> 5 | BM21: =IF(BL21="","",BL21+1) -> 6 | BN21: =IF(BM21="","",BM21+1) -> 7 | BO21: =IF(BN21="","",BN21+1) -> 8 | ... GX21: =IF(GW21="","",GW21+1) -> 147
A22: Vitis | B22: 2 | C22: Los Cambulos | D22: 21 | E22: Los Cambulos-21 | F22: Deli x Mezcla | G22: Mezcla | H22: 2009 | I22: 17 | J22: 43.34 | K22: 0 | L22: 6124 | M22: 6124 | N22: Vitis Olei | O22: Propio | P22: Productivo | Q22: =IF(R22="","",'Dashboard Ciclos'!$B$2-R22) -> 46241 | R22: =IF($E22="","",IFERROR(INDEX($W22:$GX22,MATCH('Dashboard Ciclos'!$B$2,$W$1:$GX$1,0)),"")) -> 8 | S22: =IF($Q22="","Sin dato",IF($R22<=CicloObjetivo,"En ciclo",IF($R22-CicloObjetivo<=5,"Vencido 1-5 d",IF($R22-CicloObjetivo<=10,"Vencido 6-10 d",IF($R22-CicloObjetivo<=15,"Vencido 11-15 d","Vencido +15 d"))))) -> En ciclo | T22: =IF($Q22="","Sin dato",IF($R22<VentanaCosecha,"Recién cortado",IF($R22<=CicloObjetivo,"En ciclo","Fuera de ciclo"))) -> En ciclo | U22: =IF($Q22="","",CicloObjetivo-$R22) -> 4 | V22: =IF($Q22="","",$Q22+CicloObjetivo) -> 46253 | W22: =+X22-1 -> 18 | X22: =+Y22-1 -> 19 | Y22: =+Z22-1 -> 20 | Z22: =+AA22-1 -> 21 | AA22: 22 | AB22: =IF(AA22="","",AA22+1) -> 23 | AC22: =IF(AB22="","",AB22+1) -> 24 | AD22: =IF(AC22="","",AC22+1) -> 25 | AE22: =IF(AD22="","",AD22+1) -> 26 | AF22: =IF(AE22="","",AE22+1) -> 27 | AG22: =IF(AF22="","",AF22+1) -> 28 | AH22: =IF(AG22="","",AG22+1) -> 29 | AI22: =IF(AH22="","",AH22+1) -> 30 | ... AL22: =IF(AK22="","",AK22+1) -> 33 | AM22: 0 | AN22: =IF(AM22="","",AM22+1) -> 1 | AO22: =IF(AN22="","",AN22+1) -> 2 | AP22: =IF(AO22="","",AO22+1) -> 3 | AQ22: =IF(AP22="","",AP22+1) -> 4 | AR22: =IF(AQ22="","",AQ22+1) -> 5 | AS22: =IF(AR22="","",AR22+1) -> 6 | AT22: =IF(AS22="","",AS22+1) -> 7 | AU22: =IF(AT22="","",AT22+1) -> 8 | ... BG22: =IF(BF22="","",BF22+1) -> 20 | BH22: 0 | BI22: =IF(BH22="","",BH22+1) -> 1 | BJ22: =IF(BI22="","",BI22+1) -> 2 | BK22: =IF(BJ22="","",BJ22+1) -> 3 | BL22: =IF(BK22="","",BK22+1) -> 4 | BM22: =IF(BL22="","",BL22+1) -> 5 | BN22: =IF(BM22="","",BM22+1) -> 6 | BO22: =IF(BN22="","",BN22+1) -> 7 | BP22: =IF(BO22="","",BO22+1) -> 8 | ... GX22: =IF(GW22="","",GW22+1) -> 146
A23: Vitis | B23: 2 | C23: La Vitrina | D23: 22 | E23: La Vitrina-22 | F23: Deli x Nigeria | G23: Asd | H23: 2009 | I23: 17 | J23: 33.73 | K23: 0 | L23: 4743 | M23: 4743 | N23: Vitis Olei | O23: Propio | P23: Productivo | Q23: =IF(R23="","",'Dashboard Ciclos'!$B$2-R23) -> 46234 | R23: =IF($E23="","",IFERROR(INDEX($W23:$GX23,MATCH('Dashboard Ciclos'!$B$2,$W$1:$GX$1,0)),"")) -> 15 | S23: =IF($Q23="","Sin dato",IF($R23<=CicloObjetivo,"En ciclo",IF($R23-CicloObjetivo<=5,"Vencido 1-5 d",IF($R23-CicloObjetivo<=10,"Vencido 6-10 d",IF($R23-CicloObjetivo<=15,"Vencido 11-15 d","Vencido +15 d"))))) -> Vencido 1-5 d | T23: =IF($Q23="","Sin dato",IF($R23<VentanaCosecha,"Recién cortado",IF($R23<=CicloObjetivo,"En ciclo","Fuera de ciclo"))) -> Fuera de ciclo | U23: =IF($Q23="","",CicloObjetivo-$R23) -> -3 | V23: =IF($Q23="","",$Q23+CicloObjetivo) -> 46246 | W23: =+X23-1 -> 25 | X23: =+Y23-1 -> 26 | Y23: =+Z23-1 -> 27 | Z23: =+AA23-1 -> 28 | AA23: 29 | AB23: =IF(AA23="","",AA23+1) -> 30 | AC23: =IF(AB23="","",AB23+1) -> 31 | AD23: =IF(AC23="","",AC23+1) -> 32 | AE23: 0 | AF23: =IF(AE23="","",AE23+1) -> 1 | AG23: =IF(AF23="","",AF23+1) -> 2 | AH23: =IF(AG23="","",AG23+1) -> 3 | AI23: =IF(AH23="","",AH23+1) -> 4 | AJ23: =IF(AI23="","",AI23+1) -> 5 | AK23: =IF(AJ23="","",AJ23+1) -> 6 | AL23: =IF(AK23="","",AK23+1) -> 7 | AM23: =IF(AL23="","",AL23+1) -> 8 | ... AZ23: =IF(AY23="","",AY23+1) -> 21 | BA23: 0 | BB23: =IF(BA23="","",BA23+1) -> 1 | BC23: =IF(BB23="","",BB23+1) -> 2 | BD23: =IF(BC23="","",BC23+1) -> 3 | BE23: =IF(BD23="","",BD23+1) -> 4 | BF23: =IF(BE23="","",BE23+1) -> 5 | BG23: =IF(BF23="","",BF23+1) -> 6 | BH23: =IF(BG23="","",BG23+1) -> 7 | BI23: =IF(BH23="","",BH23+1) -> 8 | ... GX23: =IF(GW23="","",GW23+1) -> 153
A24: Vitis | B24: 3 | C24: La Bendición | D24: 23 | E24: La Bendición-23 | F24: Deli x La Me | G24: Mezcla | H24: 2009 | I24: 17 | J24: 40.25 | K24: 0 | L24: 5711 | M24: 5711 | N24: Vitis Olei | O24: Propio | P24: Productivo | Q24: =IF(R24="","",'Dashboard Ciclos'!$B$2-R24) -> 46239 | R24: =IF($E24="","",IFERROR(INDEX($W24:$GX24,MATCH('Dashboard Ciclos'!$B$2,$W$1:$GX$1,0)),"")) -> 10 | S24: =IF($Q24="","Sin dato",IF($R24<=CicloObjetivo,"En ciclo",IF($R24-CicloObjetivo<=5,"Vencido 1-5 d",IF($R24-CicloObjetivo<=10,"Vencido 6-10 d",IF($R24-CicloObjetivo<=15,"Vencido 11-15 d","Vencido +15 d"))))) -> En ciclo | T24: =IF($Q24="","Sin dato",IF($R24<VentanaCosecha,"Recién cortado",IF($R24<=CicloObjetivo,"En ciclo","Fuera de ciclo"))) -> En ciclo | U24: =IF($Q24="","",CicloObjetivo-$R24) -> 2 | V24: =IF($Q24="","",$Q24+CicloObjetivo) -> 46251 | W24: =+X24-1 -> 5 | X24: =+Y24-1 -> 6 | Y24: =+Z24-1 -> 7 | Z24: =+AA24-1 -> 8 | AA24: 9 | AB24: =IF(AA24="","",AA24+1) -> 10 | AC24: =IF(AB24="","",AB24+1) -> 11 | AD24: =IF(AC24="","",AC24+1) -> 12 | AE24: =IF(AD24="","",AD24+1) -> 13 | AF24: =IF(AE24="","",AE24+1) -> 14 | AG24: =IF(AF24="","",AF24+1) -> 15 | AH24: =IF(AG24="","",AG24+1) -> 16 | AI24: =IF(AH24="","",AH24+1) -> 17 | ... AL24: =IF(AK24="","",AK24+1) -> 20 | AM24: 0 | AN24: =IF(AM24="","",AM24+1) -> 1 | AO24: =IF(AN24="","",AN24+1) -> 2 | AP24: =IF(AO24="","",AO24+1) -> 3 | AQ24: =IF(AP24="","",AP24+1) -> 4 | AR24: =IF(AQ24="","",AQ24+1) -> 5 | AS24: =IF(AR24="","",AR24+1) -> 6 | AT24: =IF(AS24="","",AS24+1) -> 7 | AU24: =IF(AT24="","",AT24+1) -> 8 | ... BE24: =IF(BD24="","",BD24+1) -> 18 | BF24: 0 | BG24: =IF(BF24="","",BF24+1) -> 1 | BH24: =IF(BG24="","",BG24+1) -> 2 | BI24: =IF(BH24="","",BH24+1) -> 3 | BJ24: =IF(BI24="","",BI24+1) -> 4 | BK24: =IF(BJ24="","",BJ24+1) -> 5 | BL24: =IF(BK24="","",BK24+1) -> 6 | BM24: =IF(BL24="","",BL24+1) -> 7 | BN24: =IF(BM24="","",BM24+1) -> 8 | ... GX24: =IF(GW24="","",GW24+1) -> 148
A25: Vitis | B25: 3 | C25: La Bendición | D25: 24 | E25: La Bendición-24 | F25: Deli x Mezcla | G25: Mezcla | H25: 2009 | I25: 17 | J25: 39.01 | K25: 0 | L25: 5480 | M25: 5480 | N25: Vitis Olei | O25: Propio | P25: Productivo | Q25: =IF(R25="","",'Dashboard Ciclos'!$B$2-R25) -> 46233 | R25: =IF($E25="","",IFERROR(INDEX($W25:$GX25,MATCH('Dashboard Ciclos'!$B$2,$W$1:$GX$1,0)),"")) -> 16 | S25: =IF($Q25="","Sin dato",IF($R25<=CicloObjetivo,"En ciclo",IF($R25-CicloObjetivo<=5,"Vencido 1-5 d",IF($R25-CicloObjetivo<=10,"Vencido 6-10 d",IF($R25-CicloObjetivo<=15,"Vencido 11-15 d","Vencido +15 d"))))) -> Vencido 1-5 d | T25: =IF($Q25="","Sin dato",IF($R25<VentanaCosecha,"Recién cortado",IF($R25<=CicloObjetivo,"En ciclo","Fuera de ciclo"))) -> Fuera de ciclo | U25: =IF($Q25="","",CicloObjetivo-$R25) -> -4 | V25: =IF($Q25="","",$Q25+CicloObjetivo) -> 46245 | W25: =+X25-1 -> 14 | X25: =+Y25-1 -> 15 | Y25: =+Z25-1 -> 16 | Z25: =+AA25-1 -> 17 | AA25: 18 | AB25: =IF(AA25="","",AA25+1) -> 19 | AC25: =IF(AB25="","",AB25+1) -> 20 | AD25: =IF(AC25="","",AC25+1) -> 21 | AE25: =IF(AD25="","",AD25+1) -> 22 | AF25: =IF(AE25="","",AE25+1) -> 23 | AG25: =IF(AF25="","",AF25+1) -> 24 | AH25: 0 | AI25: =IF(AH25="","",AH25+1) -> 1 | AJ25: =IF(AI25="","",AI25+1) -> 2 | AK25: =IF(AJ25="","",AJ25+1) -> 3 | AL25: =IF(AK25="","",AK25+1) -> 4 | AM25: =IF(AL25="","",AL25+1) -> 5 | AN25: =IF(AM25="","",AM25+1) -> 6 | AO25: =IF(AN25="","",AN25+1) -> 7 | AP25: =IF(AO25="","",AO25+1) -> 8 | ... AY25: =IF(AX25="","",AX25+1) -> 17 | AZ25: 0 | BA25: =IF(AZ25="","",AZ25+1) -> 1 | BB25: =IF(BA25="","",BA25+1) -> 2 | BC25: =IF(BB25="","",BB25+1) -> 3 | BD25: =IF(BC25="","",BC25+1) -> 4 | BE25: =IF(BD25="","",BD25+1) -> 5 | BF25: =IF(BE25="","",BE25+1) -> 6 | BG25: =IF(BF25="","",BF25+1) -> 7 | BH25: =IF(BG25="","",BG25+1) -> 8 | ... GX25: =IF(GW25="","",GW25+1) -> 154
A26: Vitis | B26: 3 | C26: La Bendición | D26: 25 | E26: La Bendición-25 | F26: Deli x La Me | G26: Irho | H26: 2009 | I26: 17 | J26: 48.99 | K26: 41 | L26: 7024 | M26: 6983 | N26: Vitis Olei | O26: Propio | P26: Productivo | Q26: =IF(R26="","",'Dashboard Ciclos'!$B$2-R26) -> 46248 | R26: =IF($E26="","",IFERROR(INDEX($W26:$GX26,MATCH('Dashboard Ciclos'!$B$2,$W$1:$GX$1,0)),"")) -> 1 | S26: =IF($Q26="","Sin dato",IF($R26<=CicloObjetivo,"En ciclo",IF($R26-CicloObjetivo<=5,"Vencido 1-5 d",IF($R26-CicloObjetivo<=10,"Vencido 6-10 d",IF($R26-CicloObjetivo<=15,"Vencido 11-15 d","Vencido +15 d"))))) -> En ciclo | T26: =IF($Q26="","Sin dato",IF($R26<VentanaCosecha,"Recién cortado",IF($R26<=CicloObjetivo,"En ciclo","Fuera de ciclo"))) -> Recién cortado | U26: =IF($Q26="","",CicloObjetivo-$R26) -> 11 | V26: =IF($Q26="","",$Q26+CicloObjetivo) -> 46260 | W26: =+X26-1 -> 14 | X26: =+Y26-1 -> 15 | Y26: =+Z26-1 -> 16 | Z26: =+AA26-1 -> 17 | AA26: 18 | AB26: =IF(AA26="","",AA26+1) -> 19 | AC26: =IF(AB26="","",AB26+1) -> 20 | AD26: =IF(AC26="","",AC26+1) -> 21 | AE26: =IF(AD26="","",AD26+1) -> 22 | AF26: =IF(AE26="","",AE26+1) -> 23 | AG26: =IF(AF26="","",AF26+1) -> 24 | AH26: 0 | AI26: =IF(AH26="","",AH26+1) -> 1 | AJ26: =IF(AI26="","",AI26+1) -> 2 | AK26: =IF(AJ26="","",AJ26+1) -> 3 | AL26: =IF(AK26="","",AK26+1) -> 4 | AM26: =IF(AL26="","",AL26+1) -> 5 | AN26: =IF(AM26="","",AM26+1) -> 6 | AO26: =IF(AN26="","",AN26+1) -> 7 | AP26: =IF(AO26="","",AO26+1) -> 8 | ... AZ26: =IF(AY26="","",AY26+1) -> 18 | BA26: 0 | BB26: =IF(BA26="","",BA26+1) -> 1 | BC26: =IF(BB26="","",BB26+1) -> 2 | BD26: =IF(BC26="","",BC26+1) -> 3 | BE26: =IF(BD26="","",BD26+1) -> 4 | BF26: =IF(BE26="","",BE26+1) -> 5 | BG26: =IF(BF26="","",BF26+1) -> 6 | BH26: =IF(BG26="","",BG26+1) -> 7 | BI26: =IF(BH26="","",BH26+1) -> 8 | ... BN26: =IF(BM26="","",BM26+1) -> 13 | BO26: 0 | BP26: =IF(BO26="","",BO26+1) -> 1 | BQ26: =IF(BP26="","",BP26+1) -> 2 | BR26: =IF(BQ26="","",BQ26+1) -> 3 | BS26: =IF(BR26="","",BR26+1) -> 4 | BT26: =IF(BS26="","",BS26+1) -> 5 | BU26: =IF(BT26="","",BT26+1) -> 6 | BV26: =IF(BU26="","",BU26+1) -> 7 | BW26: =IF(BV26="","",BV26+1) -> 8 | ... GX26: =IF(GW26="","",GW26+1) -> 139
